Workbook

Sheet Sectorizacion Racks
B1: =IFERROR(VLOOKUP('Sectorizacion Racks'!$G1,'Consulta Stock'!$D$2:$F$5447,5,FALSE),"") | E1: Columna1 | F1: Ubicación | G1: Codigos | H1: Categoria | I1: Descripcion | J1: Cantidad | L1: Fecha | M1: Lote | N1: Fecha: | O1: =+TODAY() -> 46254
A2: 1 | B2: 1 | C2: A | D2: =IF(AND('Sectorizacion Racks'!$B2=B1,C1='Sectorizacion Racks'!$C2),D1+1,1) -> 1 | E2: =+CONCATENATE('Sectorizacion Racks'!$C2,'Sectorizacion Racks'!$D2) -> A1 | F2: =+CONCATENATE(B2,C2,D2) -> 1A1 | G2: 46694 | H2: =IFERROR(VLOOKUP(G2,'Consulta Stock'!$E$2:$G$5087,3,0),"") -> ALIMENTOS INFANTILES | I2: =IFERROR(VLOOKUP('Sectorizacion Racks'!$G2,'Consulta Stock'!$E$2:$F$5447,2,FALSE),"") -> NATURNES Carne Verduras 4(6x205g) CL 4(6x205g) | J2: 100 | L2: 46631
A3: 2 | B3: 1 | C3: A | D3: =IF(AND('Sectorizacion Racks'!$B3=B2,C2='Sectorizacion Racks'!$C3),D2+1,1) -> 2 | E3: =+CONCATENATE('Sectorizacion Racks'!$C3,'Sectorizacion Racks'!$D3) -> A2 | F3: =+CONCATENATE(B3,C3,D3) -> 1A2 | G3: 14171 | H3: =IFERROR(VLOOKUP(G3,'Consulta Stock'!$E$2:$G$5087,3,0),"") -> CAFES | I3: =IFERROR(VLOOKUP('Sectorizacion Racks'!$G3,'Consulta Stock'!$E$2:$F$5447,2,FALSE),"") -> NESCAFE Caramelo Latte 6(8x18g) CL 6(8x18g) | J3: 175 | L3: 46539 | O3: Codigo
A4: 3 | B4: 1 | C4: A | D4: =IF(AND('Sectorizacion Racks'!$B4=B3,C3='Sectorizacion Racks'!$C4),D3+1,1) -> 3 | E4: =+CONCATENATE('Sectorizacion Racks'!$C4,'Sectorizacion Racks'!$D4) -> A3 | F4: =+CONCATENATE(B4,C4,D4) -> 1A3 | H4: =IFERROR(VLOOKUP(G4,'Consulta Stock'!$E$2:$G$5087,3,0),"") | I4: =IFERROR(VLOOKUP('Sectorizacion Racks'!$G4,'Consulta Stock'!$E$2:$F$5447,2,FALSE),"") | O4: Cantidad | P4: =COUNTIF(G2:G1770,P3) -> 0
A5: 4 | B5: 1 | C5: A | D5: =IF(AND('Sectorizacion Racks'!$B5=B4,C4='Sectorizacion Racks'!$C5),D4+1,1) -> 4 | E5: =+CONCATENATE('Sectorizacion Racks'!$C5,'Sectorizacion Racks'!$D5) -> A4 | F5: =+CONCATENATE(B5,C5,D5) -> 1A4 | G5: 68130 | H5: =IFERROR(VLOOKUP(G5,'Consulta Stock'!$E$2:$G$5087,3,0),"") -> OPPB | I5: =IFERROR(VLOOKUP('Sectorizacion Racks'!$G5,'Consulta Stock'!$E$2:$F$5447,2,FALSE),"") -> MILO ACTIV-GO Stabilo 36x150g N1 CL 36x150g | J5: 48 | L5: 46753 | O5: U.V. | P5: Fracción
A6: 5 | B6: 1 | C6: A | D6: =IF(AND('Sectorizacion Racks'!$B6=B5,C5='Sectorizacion Racks'!$C6),D5+1,1) -> 5 | E6: =+CONCATENATE('Sectorizacion Racks'!$C6,'Sectorizacion Racks'!$D6) -> A5 | F6: =+CONCATENATE(B6,C6,D6) -> 1A5 | G6: 5320 | H6: =IFERROR(VLOOKUP(G6,'Consulta Stock'!$E$2:$G$5087,3,0),"") -> CAFES | I6: =IFERROR(VLOOKUP('Sectorizacion Racks'!$G6,'Consulta Stock'!$E$2:$F$5447,2,FALSE),"") -> Cafe NESCAFE Tradicion sobres 77x172.8g | J6: 6 | L6: 46935 | O6: =VLOOKUP(P3,'Stock Diario'!A2:C4000,2,FALSE) | P6: =VLOOKUP(P3,'Stock Diario'!A2:C4000,3,FALSE)
A7: 6 | B7: 1 | C7: A | D7: =IF(AND('Sectorizacion Racks'!$B7=B6,C6='Sectorizacion Racks'!$C7),D6+1,1) -> 6 | E7: =+CONCATENATE('Sectorizacion Racks'!$C7,'Sectorizacion Racks'!$D7) -> A6 | F7: =+CONCATENATE(B7,C7,D7) -> 1A6 | G7: 46694 | H7: =IFERROR(VLOOKUP(G7,'Consulta Stock'!$E$2:$G$5087,3,0),"") -> ALIMENTOS INFANTILES | I7: =IFERROR(VLOOKUP('Sectorizacion Racks'!$G7,'Consulta Stock'!$E$2:$F$5447,2,FALSE),"") -> NATURNES Carne Verduras 4(6x205g) CL 4(6x205g) | J7: 100 | L7: 46631
A8: 7 | B8: 1 | C8: A | D8: =IF(AND('Sectorizacion Racks'!$B8=B7,C7='Sectorizacion Racks'!$C8),D7+1,1) -> 7 | E8: =+CONCATENATE('Sectorizacion Racks'!$C8,'Sectorizacion Racks'!$D8) -> A7 | F8: =+CONCATENATE(B8,C8,D8) -> 1A7 | G8: 5320 | H8: =IFERROR(VLOOKUP(G8,'Consulta Stock'!$E$2:$G$5087,3,0),"") -> CAFES | I8: =IFERROR(VLOOKUP('Sectorizacion Racks'!$G8,'Consulta Stock'!$E$2:$F$5447,2,FALSE),"") -> Cafe NESCAFE Tradicion sobres 77x172.8g | J8: 6 | L8: 46569 | O8: RACKS
A9: 8 | B9: 1 | C9: A | D9: =IF(AND('Sectorizacion Racks'!$B9=B8,C8='Sectorizacion Racks'!$C9),D8+1,1) -> 8 | E9: =+CONCATENATE('Sectorizacion Racks'!$C9,'Sectorizacion Racks'!$D9) -> A8 | F9: =+CONCATENATE(B9,C9,D9) -> 1A8 | G9: 5670 | H9: =IFERROR(VLOOKUP(G9,'Consulta Stock'!$E$2:$G$5087,3,0),"") -> ALIMENTOS INFANTILES | I9: =IFERROR(VLOOKUP('Sectorizacion Racks'!$G9,'Consulta Stock'!$E$2:$F$5447,2,FALSE),"") -> Colado NESTLE NATURNES Carne Verdura 8(6x115g) | J9: 84 | L9: 46569 | O9: Vacias | P9: =COUNTBLANK(G2:G784) -> 86 | Q9: =P9/P11 -> 0.10983397
A10: 9 | B10: 1 | C10: A | D10: =IF(AND('Sectorizacion Racks'!$B10=B9,C9='Sectorizacion Racks'!$C10),D9+1,1) -> 9 | E10: =+CONCATENATE('Sectorizacion Racks'!$C10,'Sectorizacion Racks'!$D10) -> A9 | F10: =+CONCATENATE(B10,C10,D10) -> 1A9 | H10: =IFERROR(VLOOKUP(G10,'Consulta Stock'!$E$2:$G$5087,3,0),"") | I10: =IFERROR(VLOOKUP('Sectorizacion Racks'!$G10,'Consulta Stock'!$E$2:$F$5447,2,FALSE),"") | O10: Usadas | P10: =COUNTA(G2:G784) -> 697 | Q10: =P10/P11 -> 0.89016603
A11: 10 | B11: 1 | C11: A | D11: =IF(AND('Sectorizacion Racks'!$B11=B10,C10='Sectorizacion Racks'!$C11),D10+1,1) -> 10 | E11: =+CONCATENATE('Sectorizacion Racks'!$C11,'Sectorizacion Racks'!$D11) -> A10 | F11: =+CONCATENATE(B11,C11,D11) -> 1A10 | G11: 63550 | I11: =IFERROR(VLOOKUP('Sectorizacion Racks'!$G11,'Consulta Stock'!$E$2:$F$5447,2,FALSE),"") -> LECHE SUR Sucedaneo LC Tarro 48x397g | J11: 48 | L11: 46539 | O11: Total en Rack | P11: =SUM(P9:P10) -> 783 | Q11: =Q9+Q10 -> 1
A12: 11 | B12: 1 | C12: A | D12: =IF(AND('Sectorizacion Racks'!$B12=B11,C11='Sectorizacion Racks'!$C12),D11+1,1) -> 11 | E12: =+CONCATENATE('Sectorizacion Racks'!$C12,'Sectorizacion Racks'!$D12) -> A11 | F12: =+CONCATENATE(B12,C12,D12) -> 1A11 | H12: =IFERROR(VLOOKUP(G12,'Consulta Stock'!$E$2:$G$5087,3,0),"") | I12: =IFERROR(VLOOKUP('Sectorizacion Racks'!$G12,'Consulta Stock'!$E$2:$F$5447,2,FALSE),"")
A13: 12 | B13: 1 | C13: A | D13: =IF(AND('Sectorizacion Racks'!$B13=B12,C12='Sectorizacion Racks'!$C13),D12+1,1) -> 12 | E13: =+CONCATENATE('Sectorizacion Racks'!$C13,'Sectorizacion Racks'!$D13) -> A12 | F13: =+CONCATENATE(B13,C13,D13) -> 1A12 | G13: 46694 | H13: =IFERROR(VLOOKUP(G13,'Consulta Stock'!$E$2:$G$5087,3,0),"") -> ALIMENTOS INFANTILES | I13: =IFERROR(VLOOKUP('Sectorizacion Racks'!$G13,'Consulta Stock'!$E$2:$F$5447,2,FALSE),"") -> NATURNES Carne Verduras 4(6x205g) CL 4(6x205g) | J13: 100 | L13: 46631 | O13: Pulmon (a piso)
A14: 13 | B14: 1 | C14: A | D14: =IF(AND('Sectorizacion Racks'!$B14=B13,C13='Sectorizacion Racks'!$C14),D13+1,1) -> 13 | E14: =+CONCATENATE('Sectorizacion Racks'!$C14,'Sectorizacion Racks'!$D14) -> A13 | F14: =+CONCATENATE(B14,C14,D14) -> 1A13 | G14: 38850 | H14: =IFERROR(VLOOKUP(G14,'Consulta Stock'!$E$2:$G$5087,3,0),"") -> CAFES | I14: =IFERROR(VLOOKUP('Sectorizacion Racks'!$G14,'Consulta Stock'!$E$2:$F$5447,2,FALSE),"") -> Cafe NESCAFE Tradicion tarro 24x50g | J14: 98 | L14: 46905 | O14: Vacias | P14: =COUNTBLANK(G785:G1212)+COUNTBLANK(G1247:G1270)+COUNTBLANK(G1471:G1486)+COUNTBLANK(G1727:G1766) -> 208 | Q14: =P14/P16 -> 0.40944882
A15: 14 | B15: 1 | C15: A | D15: =IF(AND('Sectorizacion Racks'!$B15=B14,C14='Sectorizacion Racks'!$C15),D14+1,1) -> 14 | E15: =+CONCATENATE('Sectorizacion Racks'!$C15,'Sectorizacion Racks'!$D15) -> A14 | F15: =+CONCATENATE(B15,C15,D15) -> 1A14 | H15: =IFERROR(VLOOKUP(G15,'Consulta Stock'!$E$2:$G$5087,3,0),"") | I15: =IFERROR(VLOOKUP('Sectorizacion Racks'!$G15,'Consulta Stock'!$E$2:$F$5447,2,FALSE),"") | O15: Usadas | P15: =COUNTA(G785:G1212)+COUNTA(G1247:G1270)+COUNTA(G1471:G1486)+COUNTA(G1727:G1766) -> 300 | Q15: =P15/P16 -> 0.59055118
A16: 15 | B16: 1 | C16: A | D16: =IF(AND('Sectorizacion Racks'!$B16=B15,C15='Sectorizacion Racks'!$C16),D15+1,1) -> 15 | E16: =+CONCATENATE('Sectorizacion Racks'!$C16,'Sectorizacion Racks'!$D16) -> A15 | F16: =+CONCATENATE(B16,C16,D16) -> 1A15 | G16: 68940 | H16: =IFERROR(VLOOKUP(G16,'Consulta Stock'!$E$2:$G$5087,3,0),"") -> OPPB | I16: =IFERROR(VLOOKUP('Sectorizacion Racks'!$G16,'Consulta Stock'!$E$2:$F$5447,2,FALSE),"") -> MILO ACTIV-GO BebChocStabilo 15x1000g | J16: 24 | L16: 46692 | O16: Total a Piso | P16: =SUM(P14:P15) -> 508 | Q16: =Q14+Q15 -> 1
A17: 16 | B17: 1 | C17: A | D17: =IF(AND('Sectorizacion Racks'!$B17=B16,C16='Sectorizacion Racks'!$C17),D16+1,1) -> 16 | E17: =+CONCATENATE('Sectorizacion Racks'!$C17,'Sectorizacion Racks'!$D17) -> A16 | F17: =+CONCATENATE(B17,C17,D17) -> 1A16 | H17: =IFERROR(VLOOKUP(G17,'Consulta Stock'!$E$2:$G$5087,3,0),"") | I17: =IFERROR(VLOOKUP('Sectorizacion Racks'!$G17,'Consulta Stock'!$E$2:$F$5447,2,FALSE),"")
A18: 17 | B18: 1 | C18: A | D18: =IF(AND('Sectorizacion Racks'!$B18=B17,C17='Sectorizacion Racks'!$C18),D17+1,1) -> 17 | E18: =+CONCATENATE('Sectorizacion Racks'!$C18,'Sectorizacion Racks'!$D18) -> A17 | F18: =+CONCATENATE(B18,C18,D18) -> 1A17 | G18: 43020 | H18: =IFERROR(VLOOKUP(G18,'Consulta Stock'!$E$2:$G$5087,3,0),"") -> Lacteos Culinarios | I18: =IFERROR(VLOOKUP('Sectorizacion Racks'!$G18,'Consulta Stock'!$E$2:$F$5447,2,FALSE),"") -> Manjar NESTLE El Manjar 24x500g | J18: 66 | L18: 46478 | O18: Total Posiciones | P18: =P11+P16 -> 1291
A19: 18 | B19: 1 | C19: A | D19: =IF(AND('Sectorizacion Racks'!$B19=B18,C18='Sectorizacion Racks'!$C19),D18+1,1) -> 18 | E19: =+CONCATENATE('Sectorizacion Racks'!$C19,'Sectorizacion Racks'!$D19) -> A18 | F19: =+CONCATENATE(B19,C19,D19) -> 1A18 | G19: 68940 | H19: =IFERROR(VLOOKUP(G19,'Consulta Stock'!$E$2:$G$5087,3,0),"") -> OPPB | I19: =IFERROR(VLOOKUP('Sectorizacion Racks'!$G19,'Consulta Stock'!$E$2:$F$5447,2,FALSE),"") -> MILO ACTIV-GO BebChocStabilo 15x1000g | J19: 24 | L19: 46753
A20: 19 | B20: 1 | C20: A | D20: =IF(AND('Sectorizacion Racks'!$B20=B19,C19='Sectorizacion Racks'!$C20),D19+1,1) -> 19 | E20: =+CONCATENATE('Sectorizacion Racks'!$C20,'Sectorizacion Racks'!$D20) -> A19 | F20: =+CONCATENATE(B20,C20,D20) -> 1A19 | G20: 46716 | H20: =IFERROR(VLOOKUP(G20,'Consulta Stock'!$E$2:$G$5087,3,0),"") -> ALIMENTOS INFANTILES | I20: =IFERROR(VLOOKUP('Sectorizacion Racks'!$G20,'Consulta Stock'!$E$2:$F$5447,2,FALSE),"") -> NESTLE AIP Pollo Verduras 4(6x205g) CL 4(6x205g) | J20: 100 | L20: 46539 | O20: RECEPCION
A21: 20 | B21: 1 | C21: A | D21: =IF(AND('Sectorizacion Racks'!$B21=B20,C20='Sectorizacion Racks'!$C21),D20+1,1) -> 20 | E21: =+CONCATENATE('Sectorizacion Racks'!$C21,'Sectorizacion Racks'!$D21) -> A20 | F21: =+CONCATENATE(B21,C21,D21) -> 1A20 | G21: 36535 | H21: =IFERROR(VLOOKUP(G21,'Consulta Stock'!$E$2:$G$5087,3,0),"") -> CAFES | I21: =IFERROR(VLOOKUP('Sectorizacion Racks'!$G21,'Consulta Stock'!$E$2:$F$5447,2,FALSE),"") -> NESCAFE CAPPUCCINO 6(8x14g) N2 CL 6(8x14g) | J21: 175 | L21: 46508 | O21: Vacias | P21: =COUNTBLANK(G1327:G1470) -> 126 | Q21: =P21/P23 -> 0.875
A22: 21 | B22: 1 | C22: A | D22: =IF(AND('Sectorizacion Racks'!$B22=B21,C21='Sectorizacion Racks'!$C22),D21+1,1) -> 21 | E22: =+CONCATENATE('Sectorizacion Racks'!$C22,'Sectorizacion Racks'!$D22) -> A21 | F22: =+CONCATENATE(B22,C22,D22) -> 1A21 | G22: 46694 | H22: =IFERROR(VLOOKUP(G22,'Consulta Stock'!$E$2:$G$5087,3,0),"") -> ALIMENTOS INFANTILES | I22: =IFERROR(VLOOKUP('Sectorizacion Racks'!$G22,'Consulta Stock'!$E$2:$F$5447,2,FALSE),"") -> NATURNES Carne Verduras 4(6x205g) CL 4(6x205g) | J22: 100 | L22: 46631 | O22: Usadas | P22: =COUNTA(G1327:G1468) -> 18 | Q22: =P22/P23 -> 0.125
A23: 22 | B23: 1 | C23: A | D23: =IF(AND('Sectorizacion Racks'!$B23=B22,C22='Sectorizacion Racks'!$C23),D22+1,1) -> 22 | E23: =+CONCATENATE('Sectorizacion Racks'!$C23,'Sectorizacion Racks'!$D23) -> A22 | F23: =+CONCATENATE(B23,C23,D23) -> 1A22 | G23: 68130 | H23: =IFERROR(VLOOKUP(G23,'Consulta Stock'!$E$2:$G$5087,3,0),"") -> OPPB | I23: =IFERROR(VLOOKUP('Sectorizacion Racks'!$G23,'Consulta Stock'!$E$2:$F$5447,2,FALSE),"") -> MILO ACTIV-GO Stabilo 36x150g N1 CL 36x150g | J23: 48 | L23: 46753 | O23: Pulmon | P23: =SUM(P21:P22) -> 144 | Q23: =Q21+Q22 -> 1
A24: 23 | B24: 1 | C24: A | D24: =IF(AND('Sectorizacion Racks'!$B24=B23,C23='Sectorizacion Racks'!$C24),D23+1,1) -> 23 | E24: =+CONCATENATE('Sectorizacion Racks'!$C24,'Sectorizacion Racks'!$D24) -> A23 | F24: =+CONCATENATE(B24,C24,D24) -> 1A23 | G24: 65820 | H24: =IFERROR(VLOOKUP(G24,'Consulta Stock'!$E$2:$G$5087,3,0),"") -> Leche en Polvo | I24: =IFERROR(VLOOKUP('Sectorizacion Racks'!$G24,'Consulta Stock'!$E$2:$F$5447,2,FALSE),"") -> NIDO Buen Dia LSP Softpack 12x700g | J24: 32 | L24: 46569
A25: 24 | B25: 1 | C25: A | D25: =IF(AND('Sectorizacion Racks'!$B25=B24,C24='Sectorizacion Racks'!$C25),D24+1,1) -> 24 | E25: =+CONCATENATE('Sectorizacion Racks'!$C25,'Sectorizacion Racks'!$D25) -> A24 | F25: =+CONCATENATE(B25,C25,D25) -> 1A24 | G25: 46695 | H25: =IFERROR(VLOOKUP(G25,'Consulta Stock'!$E$2:$G$5087,3,0),"") -> ALIMENTOS INFANTILES | I25: =IFERROR(VLOOKUP('Sectorizacion Racks'!$G25,'Consulta Stock'!$E$2:$F$5447,2,FALSE),"") -> NATURNES AIP Carne Verduras 4(6x205g) CL 4(6x205g) | J25: 100 | L25: 46661 | O25: Sobre Stock (Fuera de Posiciones)
A26: 25 | B26: 1 | C26: B | D26: =IF(AND('Sectorizacion Racks'!$B26=B25,C25='Sectorizacion Racks'!$C26),D25+1,1) -> 1 | E26: =+CONCATENATE('Sectorizacion Racks'!$C26,'Sectorizacion Racks'!$D26) -> B1 | F26: =+CONCATENATE(B26,C26,D26) -> 1B1 | G26: 5320 | H26: =IFERROR(VLOOKUP(G26,'Consulta Stock'!$E$2:$G$5087,3,0),"") -> CAFES | I26: =IFERROR(VLOOKUP('Sectorizacion Racks'!$G26,'Consulta Stock'!$E$2:$F$5447,2,FALSE),"") -> Cafe NESCAFE Tradicion sobres 77x172.8g | J26: 6 | L26: 46905 | O26: Usadas | P26: =COUNTA(G1272:G1470)+COUNTA(G1487:G1725) -> 18
A27: 26 | B27: 1 | C27: B | D27: =IF(AND('Sectorizacion Racks'!$B27=B26,C26='Sectorizacion Racks'!$C27),D26+1,1) -> 2 | E27: =+CONCATENATE('Sectorizacion Racks'!$C27,'Sectorizacion Racks'!$D27) -> B2 | F27: =+CONCATENATE(B27,C27,D27) -> 1B2 | G27: 14171 | H27: =IFERROR(VLOOKUP(G27,'Consulta Stock'!$E$2:$G$5087,3,0),"") -> CAFES | I27: =IFERROR(VLOOKUP('Sectorizacion Racks'!$G27,'Consulta Stock'!$E$2:$F$5447,2,FALSE),"") -> NESCAFE Caramelo Latte 6(8x18g) CL 6(8x18g) | J27: 175 | L27: 46569
A28: 27 | B28: 1 | C28: B | D28: =IF(AND('Sectorizacion Racks'!$B28=B27,C27='Sectorizacion Racks'!$C28),D27+1,1) -> 3 | E28: =+CONCATENATE('Sectorizacion Racks'!$C28,'Sectorizacion Racks'!$D28) -> B3 | F28: =+CONCATENATE(B28,C28,D28) -> 1B3 | G28: 36540 | H28: =IFERROR(VLOOKUP(G28,'Consulta Stock'!$E$2:$G$5087,3,0),"") -> CAFES | I28: =IFERROR(VLOOKUP('Sectorizacion Racks'!$G28,'Consulta Stock'!$E$2:$F$5447,2,FALSE),"") -> NESCAFE Doble Choca Moka 6(8x23g) XR 6(8x23g) | J28: 175 | L28: 46539 | O28: Frente Camara
A29: 28 | B29: 1 | C29: B | D29: =IF(AND('Sectorizacion Racks'!$B29=B28,C28='Sectorizacion Racks'!$C29),D28+1,1) -> 4 | E29: =+CONCATENATE('Sectorizacion Racks'!$C29,'Sectorizacion Racks'!$D29) -> B4 | F29: =+CONCATENATE(B29,C29,D29) -> 1B4 | G29: 68950 | H29: =IFERROR(VLOOKUP(G29,'Consulta Stock'!$E$2:$G$5087,3,0),"") -> OPPB | I29: =IFERROR(VLOOKUP('Sectorizacion Racks'!$G29,'Consulta Stock'!$E$2:$F$5447,2,FALSE),"") -> MILO ACTIV-GO Beb Chocolate 12x700g | J29: 35 | L29: 46753 | O29: Usadas | P29: =COUNTA(G1214:G1243) -> 4
A30: 29 | B30: 1 | C30: B | D30: =IF(AND('Sectorizacion Racks'!$B30=B29,C29='Sectorizacion Racks'!$C30),D29+1,1) -> 5 | E30: =+CONCATENATE('Sectorizacion Racks'!$C30,'Sectorizacion Racks'!$D30) -> B5 | F30: =+CONCATENATE(B30,C30,D30) -> 1B5 | G30: 68130 | H30: =IFERROR(VLOOKUP(G30,'Consulta Stock'!$E$2:$G$5087,3,0),"") -> OPPB | I30: =IFERROR(VLOOKUP('Sectorizacion Racks'!$G30,'Consulta Stock'!$E$2:$F$5447,2,FALSE),"") -> MILO ACTIV-GO Stabilo 36x150g N1 CL 36x150g | J30: 48 | L30: 46753
A31: 30 | B31: 1 | C31: B | D31: =IF(AND('Sectorizacion Racks'!$B31=B30,C30='Sectorizacion Racks'!$C31),D30+1,1) -> 6 | E31: =+CONCATENATE('Sectorizacion Racks'!$C31,'Sectorizacion Racks'!$D31) -> B6 | F31: =+CONCATENATE(B31,C31,D31) -> 1B6 | G31: 65820 | H31: =IFERROR(VLOOKUP(G31,'Consulta Stock'!$E$2:$G$5087,3,0),"") -> Leche en Polvo | I31: =IFERROR(VLOOKUP('Sectorizacion Racks'!$G31,'Consulta Stock'!$E$2:$F$5447,2,FALSE),"") -> NIDO Buen Dia LSP Softpack 12x700g | J31: 32 | L31: 46569 | O31: Total Pallets Usados
A32: 31 | B32: 1 | C32: B | D32: =IF(AND('Sectorizacion Racks'!$B32=B31,C31='Sectorizacion Racks'!$C32),D31+1,1) -> 7 | E32: =+CONCATENATE('Sectorizacion Racks'!$C32,'Sectorizacion Racks'!$D32) -> B7 | F32: =+CONCATENATE(B32,C32,D32) -> 1B7 | G32: 65820 | H32: =IFERROR(VLOOKUP(G32,'Consulta Stock'!$E$2:$G$5087,3,0),"") -> Leche en Polvo | I32: =IFERROR(VLOOKUP('Sectorizacion Racks'!$G32,'Consulta Stock'!$E$2:$F$5447,2,FALSE),"") -> NIDO Buen Dia LSP Softpack 12x700g | J32: 32 | L32: 46569 | O32: =COUNTA(G2:G1770) -> 1020
A33: 32 | B33: 1 | C33: B | D33: =IF(AND('Sectorizacion Racks'!$B33=B32,C32='Sectorizacion Racks'!$C33),D32+1,1) -> 8 | E33: =+CONCATENATE('Sectorizacion Racks'!$C33,'Sectorizacion Racks'!$D33) -> B8 | F33: =+CONCATENATE(B33,C33,D33) -> 1B8 | G33: 65820 | H33: =IFERROR(VLOOKUP(G33,'Consulta Stock'!$E$2:$G$5087,3,0),"") -> Leche en Polvo | I33: =IFERROR(VLOOKUP('Sectorizacion Racks'!$G33,'Consulta Stock'!$E$2:$F$5447,2,FALSE),"") -> NIDO Buen Dia LSP Softpack 12x700g | J33: 32 | L33: 46569
A34: 33 | B34: 1 | C34: B | D34: =IF(AND('Sectorizacion Racks'!$B34=B33,C33='Sectorizacion Racks'!$C34),D33+1,1) -> 9 | E34: =+CONCATENATE('Sectorizacion Racks'!$C34,'Sectorizacion Racks'!$D34) -> B9 | F34: =+CONCATENATE(B34,C34,D34) -> 1B9 | G34: 5320 | H34: =IFERROR(VLOOKUP(G34,'Consulta Stock'!$E$2:$G$5087,3,0),"") -> CAFES | I34: =IFERROR(VLOOKUP('Sectorizacion Racks'!$G34,'Consulta Stock'!$E$2:$F$5447,2,FALSE),"") -> Cafe NESCAFE Tradicion sobres 77x172.8g | J34: 6 | L34: 46905 | O34: BODEGA EXTERNA
A35: 34 | B35: 1 | C35: B | D35: =IF(AND('Sectorizacion Racks'!$B35=B34,C34='Sectorizacion Racks'!$C35),D34+1,1) -> 10 | E35: =+CONCATENATE('Sectorizacion Racks'!$C35,'Sectorizacion Racks'!$D35) -> B10 | F35: =+CONCATENATE(B35,C35,D35) -> 1B10 | G35: 2120 | H35: =IFERROR(VLOOKUP(G35,'Consulta Stock'!$E$2:$G$5087,3,0),"") -> CAFES | I35: =IFERROR(VLOOKUP('Sectorizacion Racks'!$G35,'Consulta Stock'!$E$2:$F$5447,2,FALSE),"") -> Cafe NESCAFE Tradicion tarro 24 x 170 GRS | J35: 32 | L35: 46813 | O35: =COUNTA(G1517:G1725) -> 0
A36: 35 | B36: 1 | C36: B | D36: =IF(AND('Sectorizacion Racks'!$B36=B35,C35='Sectorizacion Racks'!$C36),D35+1,1) -> 11 | E36: =+CONCATENATE('Sectorizacion Racks'!$C36,'Sectorizacion Racks'!$D36) -> B11 | F36: =+CONCATENATE(B36,C36,D36) -> 1B11 | G36: 65820 | H36: =IFERROR(VLOOKUP(G36,'Consulta Stock'!$E$2:$G$5087,3,0),"") -> Leche en Polvo | I36: =IFERROR(VLOOKUP('Sectorizacion Racks'!$G36,'Consulta Stock'!$E$2:$F$5447,2,FALSE),"") -> NIDO Buen Dia LSP Softpack 12x700g | J36: 32 | L36: 46569
A37: 36 | B37: 1 | C37: B | D37: =IF(AND('Sectorizacion Racks'!$B37=B36,C36='Sectorizacion Racks'!$C37),D36+1,1) -> 12 | E37: =+CONCATENATE('Sectorizacion Racks'!$C37,'Sectorizacion Racks'!$D37) -> B12 | F37: =+CONCATENATE(B37,C37,D37) -> 1B12 | G37: 36120 | H37: =IFERROR(VLOOKUP(G37,'Consulta Stock'!$E$2:$G$5087,3,0),"") -> CAFES | I37: =IFERROR(VLOOKUP('Sectorizacion Racks'!$G37,'Consulta Stock'!$E$2:$F$5447,2,FALSE),"") -> NESCAFE DECAF MYW 24x100g CL 24x100g | J37: 48 | L37: 46844
A38: 37 | B38: 1 | C38: B | D38: =IF(AND('Sectorizacion Racks'!$B38=B37,C37='Sectorizacion Racks'!$C38),D37+1,1) -> 13 | E38: =+CONCATENATE('Sectorizacion Racks'!$C38,'Sectorizacion Racks'!$D38) -> B13 | F38: =+CONCATENATE(B38,C38,D38) -> 1B13 | G38: 5320 | H38: =IFERROR(VLOOKUP(G38,'Consulta Stock'!$E$2:$G$5087,3,0),"") -> CAFES | I38: =IFERROR(VLOOKUP('Sectorizacion Racks'!$G38,'Consulta Stock'!$E$2:$F$5447,2,FALSE),"") -> Cafe NESCAFE Tradicion sobres 77x172.8g | J38: 6 | L38: 46905
A39: 38 | B39: 1 | C39: B | D39: =IF(AND('Sectorizacion Racks'!$B39=B38,C38='Sectorizacion Racks'!$C39),D38+1,1) -> 14 | E39: =+CONCATENATE('Sectorizacion Racks'!$C39,'Sectorizacion Racks'!$D39) -> B14 | F39: =+CONCATENATE(B39,C39,D39) -> 1B14 | G39: 5320 | H39: =IFERROR(VLOOKUP(G39,'Consulta Stock'!$E$2:$G$5087,3,0),"") -> CAFES | I39: =IFERROR(VLOOKUP('Sectorizacion Racks'!$G39,'Consulta Stock'!$E$2:$F$5447,2,FALSE),"") -> Cafe NESCAFE Tradicion sobres 77x172.8g | J39: 6 | L39: 46935
A40: 39 | B40: 1 | C40: B | D40: =IF(AND('Sectorizacion Racks'!$B40=B39,C39='Sectorizacion Racks'!$C40),D39+1,1) -> 15 | E40: =+CONCATENATE('Sectorizacion Racks'!$C40,'Sectorizacion Racks'!$D40) -> B15 | F40: =+CONCATENATE(B40,C40,D40) -> 1B15 | G40: 5320 | H40: =IFERROR(VLOOKUP(G40,'Consulta Stock'!$E$2:$G$5087,3,0),"") -> CAFES | I40: =IFERROR(VLOOKUP('Sectorizacion Racks'!$G40,'Consulta Stock'!$E$2:$F$5447,2,FALSE),"") -> Cafe NESCAFE Tradicion sobres 77x172.8g | J40: 6 | L40: 46905
...

Sheet Stock InfoDia
A1: Consulta_Stock_20251215 | B1: SOCIEDAD COMERCIAL PAN DE AZUCAR S.P.A.
A5: Fecha: 15-12-2025
A6: Sucursal: MATRI
A7: Bodega: BOD01
I8: Disponible | K8: Reservado | M8: Mal Estado | O8: Total
A9: Línea | B9: Categoría | C9: Agrupación | D9: Prod. Base | E9: Articulo | G9: Descripción | H9: Medidas | I9: U.V | J9: Fracción | K9: U.V | L9: Fracción | M9: U.V | N9: Fracción | O9: U.V | P9: Fracción
A10: DESHABILITADOS | B10: DESHABILITADOS | C10: DESHABILITADOS | D10: DESHABILITADOS | E10: 2 | F10: 0 | G10: PROMO AZUCAR ABL | I10: 0 | J10: 0 | K10: 0 | L10: 0 | M10: 0 | N10: 0 | O10: 0 | P10: 0
A11: DESHABILITADOS | B11: DESHABILITADOS | C11: DESHABILITADOS | D11: DESHABILITADOS | E11: 3 | F11: 0 | G11: PROMO FIDEOS | I11: 0 | J11: 0 | K11: 0 | L11: 0 | M11: 0 | N11: 0 | O11: 0 | P11: 0
A12: DESHABILITADOS | B12: DESHABILITADOS | C12: DESHABILITADOS | D12: DESHABILITADOS | E12: 4 | F12: 0 | G12: PROMO AZUCAR | I12: 0 | J12: 0 | K12: 0 | L12: 0 | M12: 0 | N12: 0 | O12: 0 | P12: 0
A13: DESHABILITADOS | B13: DESHABILITADOS | C13: DESHABILITADOS | D13: DESHABILITADOS | E13: 5 | F13: 0 | G13: COMBO 12.000 CFT BACK TO SCHOOL | I13: 0 | J13: 0 | K13: 0 | L13: 0 | M13: 0 | N13: 0 | O13: 0 | P13: 0
A14: DESHABILITADOS | B14: DESHABILITADOS | C14: DESHABILITADOS | D14: DESHABILITADOS | E14: 6 | F14: 0 | G14: COMBO 17.000 CFT BACK TO SCHOOL | I14: 0 | J14: 0 | K14: 0 | L14: 0 | M14: 0 | N14: 0 | O14: 0 | P14: 0
A15: DESHABILITADOS | B15: DESHABILITADOS | C15: DESHABILITADOS | D15: DESHABILITADOS | E15: 7 | F15: 0 | G15: COMBO 23.000 CFT BACK TO SCHOOL | I15: 0 | J15: 0 | K15: 0 | L15: 0 | M15: 0 | N15: 0 | O15: 0 | P15: 0
A16: DESHABILITADOS | B16: DESHABILITADOS | C16: DESHABILITADOS | D16: DESHABILITADOS | E16: 8 | F16: 0 | G16: SET ESCOLAR COLLEGE | I16: 0 | J16: 0 | K16: 0 | L16: 0 | M16: 0 | N16: 0 | O16: 0 | P16: 0
A17: DESHABILITADOS | B17: DESHABILITADOS | C17: DESHABILITADOS | D17: DESHABILITADOS | E17: 9 | F17: 0 | G17: SET ESCOLAR JUNIOR | I17: 0 | J17: 0 | K17: 0 | L17: 0 | M17: 0 | N17: 0 | O17: 0 | P17: 0
A18: CONFITES | B18: CHOCOLATES | C18: BOLSAS PROMO | D18: PROMO BOLSAS | E18: 10 | F18: 0 | G18: BOLSAS PROMO | H18: 28 x 35 GRS | I18: 0 | J18: 0 | K18: 0 | L18: 0 | M18: 0 | N18: 0 | O18: 0 | P18: 0
A19: TRADICIONAL | B19: CULINARIOS | C19: SET DE CUBIERTOS | D19: PROMO CUBIERTOS | E19: 11 | F19: 0 | G19: SET DE CUBIERTOS | I19: 0 | J19: 0 | K19: 0 | L19: 0 | M19: 0 | N19: 0 | O19: 0 | P19: 0
A20: TRADICIONAL | B20: CULINARIOS | C20: PROMO CULINARIO | D20: PROMO CULINARIO | E20: 12 | F20: 0 | G20: Regalo Promocional Maggi | I20: 0 | J20: 0 | K20: 0 | L20: 0 | M20: 0 | N20: 0 | O20: 0 | P20: 0
A21: TRADICIONAL | B21: CAFES | C21: EXHIBIDOR | D21: NDG Trade | E21: 13 | F21: 0 | G21: EXHIBIDOR NESCAFE | H21: 1 | I21: 0 | J21: 0 | K21: 0 | L21: 0 | M21: 0 | N21: 0 | O21: 0 | P21: 0
A22: TRADICIONAL | B22: CULINARIOS | C22: EXHIBIDOR2 | D22: EXHIBIDOR CALDOS | E22: 14 | F22: 0 | G22: DISPENSADOR MAGGI | H22: 1 | I22: 0 | J22: 0 | K22: 0 | L22: 0 | M22: 0 | N22: 0 | O22: 0 | P22: 0
A23: DESHABILITADOS | B23: DESHABILITADOS | C23: DESHABILITADOS | D23: DESHABILITADOS | E23: 15 | F23: 0 | G23: PACK 2 UNIDADES PROMO (VIN) | I23: 0 | J23: 0 | K23: 0 | L23: 0 | M23: 0 | N23: 0 | O23: 0 | P23: 0
A24: DESHABILITADOS | B24: DESHABILITADOS | C24: DESHABILITADOS | D24: DESHABILITADOS | E24: 16 | F24: 0 | G24: BANDEJA DE HUEVOS REGALO | I24: 0 | J24: 0 | K24: 0 | L24: 0 | M24: 0 | N24: 0 | O24: 0 | P24: 0
A25: DESHABILITADOS | B25: DESHABILITADOS | C25: DESHABILITADOS | D25: DESHABILITADOS | E25: 18 | F25: 0 | G25: MUEBLE GALLETA | I25: 0 | J25: 0 | K25: 0 | L25: 0 | M25: 0 | N25: 0 | O25: 0 | P25: 0
A26: CONFITES | B26: CHOCOLATES | C26: BOLSAS PROMO | D26: PROMO BOLSAS | E26: 20 | F26: 0 | G26: BOLSAS PROMO | H26: 33 x 40 GRS | I26: 0 | J26: 0 | K26: 0 | L26: 0 | M26: 0 | N26: 0 | O26: 0 | P26: 0
A27: DESHABILITADOS | B27: DESHABILITADOS | C27: DESHABILITADOS | D27: DESHABILITADOS | E27: 21 | F27: 0 | G27: KIT 2 VISIBILIDAD GALLETAS Y CHOCOLATES | H27: 1 | I27: 0 | J27: 0 | K27: 0 | L27: 0 | M27: 0 | N27: 0 | O27: 0 | P27: 0
A28: DESHABILITADOS | B28: DESHABILITADOS | C28: DESHABILITADOS | D28: DESHABILITADOS | E28: 25 | F28: 0 | G28: LAMPARA DE EMERGENCIA | H28: 1 | I28: 0 | J28: 0 | K28: 0 | L28: 0 | M28: 0 | N28: 0 | O28: 0 | P28: 0
A29: DESHABILITADOS | B29: DESHABILITADOS | C29: DESHABILITADOS | D29: DESHABILITADOS | E29: 26 | F29: 0 | G29: COMBO 1 VUELTA A CLASES | H29: 1 | I29: 0 | J29: 0 | K29: 0 | L29: 0 | M29: 0 | N29: 0 | O29: 0 | P29: 0
A30: DESHABILITADOS | B30: DESHABILITADOS | C30: DESHABILITADOS | D30: DESHABILITADOS | E30: 27 | F30: 0 | G30: COMBO 2 VUELTA A CLASES | H30: 1 | I30: 0 | J30: 0 | K30: 0 | L30: 0 | M30: 0 | N30: 0 | O30: 0 | P30: 0
A31: DESHABILITADOS | B31: DESHABILITADOS | C31: DESHABILITADOS | D31: DESHABILITADOS | E31: 28 | F31: 0 | G31: COMBO 3 VUELTA A CLASES | H31: 1 | I31: 0 | J31: 0 | K31: 0 | L31: 0 | M31: 0 | N31: 0 | O31: 0 | P31: 0
A32: DESHABILITADOS | B32: DESHABILITADOS | C32: DESHABILITADOS | D32: DESHABILITADOS | E32: 30 | F32: 0 | G32: HUEVOS + MINI BEBIDA | H32: 2 x 5 GRM | I32: 0 | J32: 0 | K32: 0 | L32: 0 | M32: 0 | N32: 0 | O32: 0 | P32: 0
A33: TRADICIONAL | B33: CAFES | C33: STANDARD | D33: Nescafe Trad | E33: 36 | F33: 0 | G33: NESCAFE TRADICIÓN TARRO | H33: 9 x 6 x 50 GRS | I33: 0 | J33: 0 | K33: 0 | L33: 0 | M33: 0 | N33: 0 | O33: 0 | P33: 0
A34: TRADICIONAL | B34: CAFES | C34: STANDARD | D34: Nescafe Trad | E34: 37 | F34: 0 | G34: NESCAFE TRADICIÓN TARRO | H34: 9 x 6 x 50 GRM | I34: 0 | J34: 0 | K34: 0 | L34: 0 | M34: 0 | N34: 0 | O34: 0 | P34: 0
A35: DESHABILITADOS | B35: DESHABILITADOS | C35: DESHABILITADOS | D35: DESHABILITADOS | E35: 39 | F35: 0 | G35: MCKAY VINO VO | H35: 28 x 155 GRM | I35: 0 | J35: 0 | K35: 0 | L35: 0 | M35: 0 | N35: 0 | O35: 0 | P35: 0
A36: TRADICIONAL | B36: OPPB | C36: NESQUIK | D36: NESQUIK | E36: 40 | F36: 0 | G36: NESQUIK NUTRB Frutilla | H36: 8 x 20 x 15 GRM | I36: 0 | J36: 0 | K36: 0 | L36: 0 | M36: 0 | N36: 0 | O36: 0 | P36: 0
A37: TRADICIONAL | B37: OPPB | C37: NESQUIK | D37: NESQUIK | E37: 41 | F37: 0 | G37: NESQUIK FRUTILLA | H37: 8 x 20 x 15 GRM | I37: 0 | J37: 0 | K37: 0 | L37: 0 | M37: 0 | N37: 0 | O37: 0 | P37: 0
A38: DESHABILITADOS | B38: DESHABILITADOS | C38: DESHABILITADOS | D38: DESHABILITADOS | E38: 43 | F38: 0 | G38: Maq Afeitar + S.Nuss 250 gr | H38: 1 | I38: 0 | J38: 0 | K38: 0 | L38: 0 | M38: 0 | N38: 0 | O38: 0 | P38: 0
A39: DESHABILITADOS | B39: DESHABILITADOS | C39: DESHABILITADOS | D39: DESHABILITADOS | E39: 44 | F39: 0 | G39: Regalo Pack x Galletas | H39: 1 | I39: 0 | J39: 0 | K39: 0 | L39: 0 | M39: 0 | N39: 0 | O39: 0 | P39: 0
A40: TRADICIONAL | B40: CAFES | C40: PACK CAFE | D40: PACK CAFE | E40: 47 | F40: 0 | G40: PACK CAFE 1 | H40: 1 | I40: 0 | J40: 0 | K40: 0 | L40: 0 | M40: 0 | N40: 0 | O40: 0 | P40: 0
A41: DESHABILITADOS | B41: DESHABILITADOS | C41: DESHABILITADOS | D41: DESHABILITADOS | E41: 49 | F41: 0 | G41: PROMO JUGO | I41: 0 | J41: 0 | K41: 0 | L41: 0 | M41: 0 | N41: 0 | O41: 0 | P41: 0
A42: CONFITES | B42: GALLETAS | C42: PACK GALLETAS | D42: PACK GALLETAS | E42: 52 | F42: 0 | G42: PACK TRITON+KUKY+MTORTA | H42: 1 | I42: 0 | J42: 0 | K42: 0 | L42: 0 | M42: 0 | N42: 0 | O42: 0 | P42: 0
A43: TRADICIONAL | B43: CULINARIOS | C43: PACK CULINARIOS | D43: PACK CULINARIOS | E43: 54 | F43: 0 | G43: PACK CULINARIO 1 | H43: 1 | I43: 0 | J43: 0 | K43: 0 | L43: 0 | M43: 0 | N43: 0 | O43: 0 | P43: 0
...

Sheet Stock Diario
A1: Articulo | B1: U.V | C1: Fracción
A2: =VALUE(CONCATENATE('Stock InfoDia'!E10,'Stock InfoDia'!F10)) -> 20 | B2: ='Stock InfoDia'!I10 -> 0 | C2: ='Stock InfoDia'!J10 -> 0
A3: =VALUE(CONCATENATE('Stock InfoDia'!E11,'Stock InfoDia'!F11)) -> 30 | B3: ='Stock InfoDia'!I11 -> 0 | C3: ='Stock InfoDia'!J11 -> 0
A4: =VALUE(CONCATENATE('Stock InfoDia'!E12,'Stock InfoDia'!F12)) -> 40 | B4: ='Stock InfoDia'!I12 -> 0 | C4: ='Stock InfoDia'!J12 -> 0
A5: =VALUE(CONCATENATE('Stock InfoDia'!E13,'Stock InfoDia'!F13)) -> 50 | B5: ='Stock InfoDia'!I13 -> 0 | C5: ='Stock InfoDia'!J13 -> 0
A6: =VALUE(CONCATENATE('Stock InfoDia'!E14,'Stock InfoDia'!F14)) -> 60 | B6: ='Stock InfoDia'!I14 -> 0 | C6: ='Stock InfoDia'!J14 -> 0
A7: =VALUE(CONCATENATE('Stock InfoDia'!E15,'Stock InfoDia'!F15)) -> 70 | B7: ='Stock InfoDia'!I15 -> 0 | C7: ='Stock InfoDia'!J15 -> 0
A8: =VALUE(CONCATENATE('Stock InfoDia'!E16,'Stock InfoDia'!F16)) -> 80 | B8: ='Stock InfoDia'!I16 -> 0 | C8: ='Stock InfoDia'!J16 -> 0
A9: =VALUE(CONCATENATE('Stock InfoDia'!E17,'Stock InfoDia'!F17)) -> 90 | B9: ='Stock InfoDia'!I17 -> 0 | C9: ='Stock InfoDia'!J17 -> 0
A10: =VALUE(CONCATENATE('Stock InfoDia'!E18,'Stock InfoDia'!F18)) -> 100 | B10: ='Stock InfoDia'!I18 -> 0 | C10: ='Stock InfoDia'!J18 -> 0
A11: =VALUE(CONCATENATE('Stock InfoDia'!E19,'Stock InfoDia'!F19)) -> 110 | B11: ='Stock InfoDia'!I19 -> 0 | C11: ='Stock InfoDia'!J19 -> 0
A12: =VALUE(CONCATENATE('Stock InfoDia'!E20,'Stock InfoDia'!F20)) -> 120 | B12: ='Stock InfoDia'!I20 -> 0 | C12: ='Stock InfoDia'!J20 -> 0
A13: =VALUE(CONCATENATE('Stock InfoDia'!E21,'Stock InfoDia'!F21)) -> 130 | B13: ='Stock InfoDia'!I21 -> 0 | C13: ='Stock InfoDia'!J21 -> 0
... A4000: =VALUE(CONCATENATE('Stock InfoDia'!E4008,'Stock InfoDia'!F4008)) -> 0 | B4000: ='Stock InfoDia'!I4008 | C4000: ='Stock InfoDia'!J4008

Sheet Cod. Concuna
A1: COD | B1: COD | C1: COD
A2: =Concuna!C2 -> 46694 | B2: =VLOOKUP(A2,Concuna!C2:E398,2,FALSE) -> Posición A01 | C2: =VLOOKUP(A2,Concuna!C2:F398,3,FALSE) -> NATURNES Carne Verduras 4(6x205g) CL
A3: =Concuna!C3 -> 46669 | B3: =VLOOKUP(A3,Concuna!C3:E399,2,FALSE) -> Posición A02 | C3: =VLOOKUP(A3,Concuna!C3:F399,3,FALSE) -> NATURNES Pollo Verduras 4(6x205g) CL
A4: =Concuna!C4 -> 46695 | B4: =VLOOKUP(A4,Concuna!C4:E400,2,FALSE) -> Posición A03 | C4: =VLOOKUP(A4,Concuna!C4:F400,3,FALSE) -> NATURNES AIP Carne Verduras 4(6x205g) CL
A5: =Concuna!C5 -> 46716 | B5: =VLOOKUP(A5,Concuna!C5:E401,2,FALSE) -> Posición A04 | C5: =VLOOKUP(A5,Concuna!C5:F401,3,FALSE) -> NESTLE AIP Pollo Verduras 4(6x205g) CL
A6: =Concuna!C6 -> 46730 | B6: =VLOOKUP(A6,Concuna!C6:E402,2,FALSE) -> Posición A05 | C6: =VLOOKUP(A6,Concuna!C6:F402,3,FALSE) -> Picado NESTLE NATURNES Carbonada12x250g
A7: =Concuna!C7 -> 46740 | B7: =VLOOKUP(A7,Concuna!C7:E403,2,FALSE) -> Posición A06 | C7: =VLOOKUP(A7,Concuna!C7:F403,3,FALSE) -> Picado NESTLE NATURNES Cazuela de Ave 24x250g
A8: =Concuna!C8 -> 46750 | B8: =VLOOKUP(A8,Concuna!C8:E404,2,FALSE) -> Posición A07 | C8: =VLOOKUP(A8,Concuna!C8:F404,3,FALSE) -> Picado NESTLE NATURNES Cazuela de Vacuno24x250g
A9: =Concuna!C9 -> 46760 | B9: =VLOOKUP(A9,Concuna!C9:E405,2,FALSE) -> Posición A08 | C9: =VLOOKUP(A9,Concuna!C9:F405,3,FALSE) -> Picado NESTLE NATURNES Charquican12x250g
A10: =Concuna!C10 -> 5670 | B10: =VLOOKUP(A10,Concuna!C10:E406,2,FALSE) -> Posición A09 | C10: =VLOOKUP(A10,Concuna!C10:F406,3,FALSE) -> Colado NESTLE NATURNES Carne Verdura 8(6x115g)
A11: =Concuna!C11 -> 56420 | B11: =VLOOKUP(A11,Concuna!C11:E407,2,FALSE) -> Posición A10 | C11: =VLOOKUP(A11,Concuna!C11:F407,3,FALSE) -> Colado NESTLE NATURNES Pollo Verduras 8x6x115g
A12: =Concuna!C12 -> 1330 | B12: =VLOOKUP(A12,Concuna!C12:E408,2,FALSE) -> Posición A11 | C12: =VLOOKUP(A12,Concuna!C12:F408,3,FALSE) -> Crema de leche NESTLE Lata48 x 157 GRM
A13: =Concuna!C13 -> 79760 | B13: =VLOOKUP(A13,Concuna!C13:E409,2,FALSE) -> Posición A11 | C13: =VLOOKUP(A13,Concuna!C13:F409,3,FALSE) -> NESTLE Crema de leche tarro 3840x157g
... A326: =Concuna!C326 -> 8410 | B326: =VLOOKUP(A326,Concuna!C326:E722,2,FALSE) -> Posición N05 | C326: =VLOOKUP(A326,Concuna!C326:F722,3,FALSE) -> TRENCITO Galleta Cubierta 40x130g
A328: =Concuna!C327 -> 36720 | B328: =VLOOKUP(A328,Concuna!C327:E723,2,FALSE) -> Posición N06 | C328: =VLOOKUP(A328,Concuna!C327:F723,3,FALSE) -> TRITON GallVainilla Tripack 10(3x116g)CL
A329: =Concuna!C328 -> 81990 | B329: =VLOOKUP(A329,Concuna!C328:E724,2,FALSE) -> Posición N07 | C329: =VLOOKUP(A329,Concuna!C328:F724,3,FALSE) -> Galletas MCKAY Niza24 x 150 GRM
A330: =Concuna!C329 -> 59010 | B330: =VLOOKUP(A330,Concuna!C329:E725,2,FALSE) -> Posición N08 | C330: =VLOOKUP(A330,Concuna!C329:F725,3,FALSE) -> Galleta GRILL Clasica12x140g
A331: =Concuna!C330 -> 36840 | B331: =VLOOKUP(A331,Concuna!C330:E726,2,FALSE) -> Posición N09 | C331: =VLOOKUP(A331,Concuna!C330:F726,3,FALSE) -> TRITON Regular ChocoWhite 30x116g CL
A332: =Concuna!C331 -> 81170 | B332: =VLOOKUP(A332,Concuna!C331:E727,2,FALSE) -> Posición N10 | C332: =VLOOKUP(A332,Concuna!C331:F727,3,FALSE) -> Galleta chip KUKY Chocolate30 x 120 GRM
A333: =Concuna!C332 -> 81160 | B333: =VLOOKUP(A333,Concuna!C332:E728,2,FALSE) -> Posición N11 | C333: =VLOOKUP(A333,Concuna!C332:F728,3,FALSE) -> Galleta chip KUKY Clasica30 x 120 GRM
A334: =Concuna!C333 -> 81160 | B334: =VLOOKUP(A334,Concuna!C333:E729,2,FALSE) -> Posición N11 | C334: =VLOOKUP(A334,Concuna!C333:F729,3,FALSE) -> Galleta chip KUKY Clasica30 x 120 GRM
A335: =Concuna!C334 -> 7910 | B335: =VLOOKUP(A335,Concuna!C334:E730,2,FALSE) -> Posición N11 | C335: =VLOOKUP(A335,Concuna!C334:F730,3,FALSE) -> MCKAY KUKY CLASICA 120g PDQ
A336: =Concuna!C335 -> 36270 | B336: =VLOOKUP(A336,Concuna!C335:E731,2,FALSE) -> Posición N12 | C336: =VLOOKUP(A336,Concuna!C335:F731,3,FALSE) -> TRENCITO ChocoCookies Brownie 40x120g CL
A337: =Concuna!C336 -> 90720 | B337: =VLOOKUP(A337,Concuna!C336:E732,2,FALSE) -> Posición N13 | C337: =VLOOKUP(A337,Concuna!C336:F732,3,FALSE) -> MOROCHA Mini Galleta 24x50g N1 CL
A338: =Concuna!C337 -> 63540 | B338: =VLOOKUP(A338,Concuna!C337:E733,2,FALSE) -> Posición N13 | C338: =VLOOKUP(A338,Concuna!C337:F733,3,FALSE) -> MOROCHA Mini Galleta PDQ
A339: =Concuna!C338 -> 68681 | B339: =VLOOKUP(A339,Concuna!C338:E734,2,FALSE) -> Posición N14 | C339: =VLOOKUP(A339,Concuna!C338:F734,3,FALSE) -> TRITON Reg GallChocolate Medio PDQ 127.6kg CL
... A351: =Concuna!C350 -> 86649 | B351: =VLOOKUP(A351,Concuna!C350:E746,2,FALSE) -> Posición O09 | C351: =VLOOKUP(A351,Concuna!C350:F746,3,FALSE) -> PK 4 SODA180GR+1TRENCITO CHOCOBISCUIT +15%DCTO
A352: =Concuna!C351 -> 357219 | B352: =VLOOKUP(A353,Concuna!C352:E748,2,FALSE) -> Posición O11 | C352: =VLOOKUP(A352,Concuna!C351:F747,3,FALSE) -> PK 2ALTFRUT +2ALTBOCA +1TRENCOATED 15%DCTO
A353: =Concuna!C352 -> 36683 | C353: =VLOOKUP(A353,Concuna!C352:F748,3,FALSE) -> PK ALTEZAS 2HELADO+2BOCADO +1CHOCOVAINILLA+15%DCTO
A354: =Concuna!C353 -> 357218 | B354: =VLOOKUP(A354,Concuna!C353:E749,2,FALSE) -> Posición O12 | C354: =VLOOKUP(A354,Concuna!C353:F749,3,FALSE) -> PK 5 Alteza Frutilla + 1 Gratis (B2B).
A355: =Concuna!C354 -> 370512 | B355: =VLOOKUP(A355,Concuna!C354:E750,2,FALSE) -> Posición O13 | C355: =VLOOKUP(A355,Concuna!C354:F750,3,FALSE) -> PK 5 Alteza Chirimoya + 1 Gratis (B2B) (DV).
A356: =Concuna!C355 -> 88824 | B356: =VLOOKUP(A356,Concuna!C355:E751,2,FALSE) -> Posición O14 | C356: =VLOOKUP(A356,Concuna!C355:F751,3,FALSE) -> PK MinTriVa+MinTriCho+MinMor+MinKu + 19.98% DCTO (B2B)
A357: =Concuna!C356 -> 87331 | B357: =VLOOKUP(A357,Concuna!C356:E752,2,FALSE) -> Posición O15 | C357: =VLOOKUP(A357,Concuna!C356:F752,3,FALSE) -> PK 4 MINI NIZA + 21.20% DCTO (B2B)
A358: =Concuna!C357 -> 87332 | B358: =VLOOKUP(A358,Concuna!C357:E753,2,FALSE) -> Posición O16 | C358: =VLOOKUP(A358,Concuna!C357:F753,3,FALSE) -> PK 4 MINI NIZA + 21.20% DCTO (DV)
A359: =Concuna!C358 -> 7282 | B359: =VLOOKUP(A359,Concuna!C358:E754,2,FALSE) -> Posición O17 | C359: =VLOOKUP(A359,Concuna!C358:F754,3,FALSE) -> PK 4 MINI MANTEQUILLA 21.20% DCTO (B2B)
A360: =Concuna!C359 -> 7283 | B360: =VLOOKUP(A360,Concuna!C359:E755,2,FALSE) -> Posición O18 | C360: =VLOOKUP(A360,Concuna!C359:F755,3,FALSE) -> PK 4 MINI MANTEQUILLA + 21.20% DCTO (DV)
A361: =Concuna!C360 -> 874613 | B361: =VLOOKUP(A361,Concuna!C360:E756,2,FALSE) -> Posición O19 | C361: =VLOOKUP(A361,Concuna!C360:F756,3,FALSE) -> PK 4 MINI VINO + 21.20% DCTO (B2B)
A362: =Concuna!C361 -> 874614 | B362: =VLOOKUP(A362,Concuna!C361:E757,2,FALSE) -> Posición O20 | C362: =VLOOKUP(A362,Concuna!C361:F757,3,FALSE) -> PK 4 MINI VINO 21.20% DCTO (DV)
A363: =Concuna!C362 -> 90711 | B363: =VLOOKUP(A363,Concuna!C362:E758,2,FALSE) -> Posición O21 | C363: =VLOOKUP(A363,Concuna!C362:F758,3,FALSE) -> PK 4 MINI LIMON + 21.20% DCTO (B2B)
A364: =Concuna!C363 -> 90712 | B364: =VLOOKUP(A364,Concuna!C363:E759,2,FALSE) -> Posición O22 | C364: =VLOOKUP(A364,Concuna!C363:F759,3,FALSE) -> PK 4 MINI LIMON + 21.20% DCTO (DV)
...

Sheet Consulta Stock
A2: CATEGORIA | B2: COD. ARTICULO | C2: DESCRIPCION | D2: MEDIDA | E2: Cod | F2: Descripcion 1 | G2: Categoria1
A3: DESHABILITADOS | B3: 02 - 0 | C3: PROMO AZUCAR ABL | E3: =VALUE(SUBSTITUTE(SUBSTITUTE(B3," ",""),"-","")) -> 20 | F3: =+CONCATENATE(C3," ",D3) -> PROMO AZUCAR ABL | G3: =A3 -> DESHABILITADOS
A4: DESHABILITADOS | B4: 03 - 0 | C4: PROMO FIDEOS | E4: =VALUE(SUBSTITUTE(SUBSTITUTE(B4," ",""),"-","")) -> 30 | F4: =+CONCATENATE(C4," ",D4) -> PROMO FIDEOS | G4: =A4 -> DESHABILITADOS
A5: DESHABILITADOS | B5: 04 - 0 | C5: PROMO AZUCAR | E5: =VALUE(SUBSTITUTE(SUBSTITUTE(B5," ",""),"-","")) -> 40 | F5: =+CONCATENATE(C5," ",D5) -> PROMO AZUCAR | G5: =A5 -> DESHABILITADOS
A6: DESHABILITADOS | B6: 05 - 0 | C6: COMBO 12.000 CFT BACK TO SCHOOL | E6: =VALUE(SUBSTITUTE(SUBSTITUTE(B6," ",""),"-","")) -> 50 | F6: =+CONCATENATE(C6," ",D6) -> COMBO 12.000 CFT BACK TO SCHOOL | G6: =A6 -> DESHABILITADOS
A7: DESHABILITADOS | B7: 06 - 0 | C7: COMBO 17.000 CFT BACK TO SCHOOL | E7: =VALUE(SUBSTITUTE(SUBSTITUTE(B7," ",""),"-","")) -> 60 | F7: =+CONCATENATE(C7," ",D7) -> COMBO 17.000 CFT BACK TO SCHOOL | G7: =A7 -> DESHABILITADOS
A8: DESHABILITADOS | B8: 07 - 0 | C8: COMBO 23.000 CFT BACK TO SCHOOL | E8: =VALUE(SUBSTITUTE(SUBSTITUTE(B8," ",""),"-","")) -> 70 | F8: =+CONCATENATE(C8," ",D8) -> COMBO 23.000 CFT BACK TO SCHOOL | G8: =A8 -> DESHABILITADOS
A9: DESHABILITADOS | B9: 08 - 0 | C9: SET ESCOLAR COLLEGE | E9: =VALUE(SUBSTITUTE(SUBSTITUTE(B9," ",""),"-","")) -> 80 | F9: =+CONCATENATE(C9," ",D9) -> SET ESCOLAR COLLEGE | G9: =A9 -> DESHABILITADOS
A10: DESHABILITADOS | B10: 09 - 0 | C10: SET ESCOLAR JUNIOR | E10: =VALUE(SUBSTITUTE(SUBSTITUTE(B10," ",""),"-","")) -> 90 | F10: =+CONCATENATE(C10," ",D10) -> SET ESCOLAR JUNIOR | G10: =A10 -> DESHABILITADOS
A11: CHOCOLATES | B11: 10 - 0 | C11: BOLSAS PROMO | D11: 28 x 35 GRS | E11: =VALUE(SUBSTITUTE(SUBSTITUTE(B11," ",""),"-","")) -> 100 | F11: =+CONCATENATE(C11," ",D11) -> BOLSAS PROMO 28 x 35 GRS | G11: =A11 -> CHOCOLATES
A12: CULINARIOS | B12: 11 - 0 | C12: SET DE CUBIERTOS | E12: =VALUE(SUBSTITUTE(SUBSTITUTE(B12," ",""),"-","")) -> 110 | F12: =+CONCATENATE(C12," ",D12) -> SET DE CUBIERTOS | G12: =A12 -> CULINARIOS
A13: CULINARIOS | B13: 12 - 0 | C13: Regalo Promocional Maggi | E13: =VALUE(SUBSTITUTE(SUBSTITUTE(B13," ",""),"-","")) -> 120 | F13: =+CONCATENATE(C13," ",D13) -> Regalo Promocional Maggi | G13: =A13 -> CULINARIOS
A14: CAFES | B14: 13 - 0 | C14: EXHIBIDOR NESCAFE | D14: 1 | E14: =VALUE(SUBSTITUTE(SUBSTITUTE(B14," ",""),"-","")) -> 130 | F14: =+CONCATENATE(C14," ",D14) -> EXHIBIDOR NESCAFE 1 | G14: =A14 -> CAFES
A15: CULINARIOS | B15: 14 - 0 | C15: DISPENSADOR MAGGI | D15: 1 | E15: =VALUE(SUBSTITUTE(SUBSTITUTE(B15," ",""),"-","")) -> 140 | F15: =+CONCATENATE(C15," ",D15) -> DISPENSADOR MAGGI 1 | G15: =A15 -> CULINARIOS
A16: DESHABILITADOS | B16: 15 - 0 | C16: PACK 2 UNIDADES PROMO (VIN) | E16: =VALUE(SUBSTITUTE(SUBSTITUTE(B16," ",""),"-","")) -> 150 | F16: =+CONCATENATE(C16," ",D16) -> PACK 2 UNIDADES PROMO (VIN) | G16: =A16 -> DESHABILITADOS
A17: DESHABILITADOS | B17: 16 - 0 | C17: BANDEJA DE HUEVOS REGALO | E17: =VALUE(SUBSTITUTE(SUBSTITUTE(B17," ",""),"-","")) -> 160 | F17: =+CONCATENATE(C17," ",D17) -> BANDEJA DE HUEVOS REGALO | G17: =A17 -> DESHABILITADOS
A18: DESHABILITADOS | B18: 18 - 0 | C18: MUEBLE GALLETA | E18: =VALUE(SUBSTITUTE(SUBSTITUTE(B18," ",""),"-","")) -> 180 | F18: =+CONCATENATE(C18," ",D18) -> MUEBLE GALLETA | G18: =A18 -> DESHABILITADOS
A19: CHOCOLATES | B19: 20 - 0 | C19: BOLSAS PROMO | D19: 33 x 40 GRS | E19: =VALUE(SUBSTITUTE(SUBSTITUTE(B19," ",""),"-","")) -> 200 | F19: =+CONCATENATE(C19," ",D19) -> BOLSAS PROMO 33 x 40 GRS | G19: =A19 -> CHOCOLATES
A20: DESHABILITADOS | B20: 21 - 0 | C20: KIT 2 VISIBILIDAD GALLETAS Y CHOCOLATES | D20: 1 | E20: =VALUE(SUBSTITUTE(SUBSTITUTE(B20," ",""),"-","")) -> 210 | F20: =+CONCATENATE(C20," ",D20) -> KIT 2 VISIBILIDAD GALLETAS Y CHOCOLATES 1 | G20: =A20 -> DESHABILITADOS
A21: DESHABILITADOS | B21: 25 - 0 | C21: LAMPARA DE EMERGENCIA | D21: 1 | E21: =VALUE(SUBSTITUTE(SUBSTITUTE(B21," ",""),"-","")) -> 250 | F21: =+CONCATENATE(C21," ",D21) -> LAMPARA DE EMERGENCIA 1 | G21: =A21 -> DESHABILITADOS
A22: DESHABILITADOS | B22: 26 - 0 | C22: COMBO 1 VUELTA A CLASES | D22: 1 | E22: =VALUE(SUBSTITUTE(SUBSTITUTE(B22," ",""),"-","")) -> 260 | F22: =+CONCATENATE(C22," ",D22) -> COMBO 1 VUELTA A CLASES 1 | G22: =A22 -> DESHABILITADOS
A23: DESHABILITADOS | B23: 27 - 0 | C23: COMBO 2 VUELTA A CLASES | D23: 1 | E23: =VALUE(SUBSTITUTE(SUBSTITUTE(B23," ",""),"-","")) -> 270 | F23: =+CONCATENATE(C23," ",D23) -> COMBO 2 VUELTA A CLASES 1 | G23: =A23 -> DESHABILITADOS
A24: DESHABILITADOS | B24: 28 - 0 | C24: COMBO 3 VUELTA A CLASES | D24: 1 | E24: =VALUE(SUBSTITUTE(SUBSTITUTE(B24," ",""),"-","")) -> 280 | F24: =+CONCATENATE(C24," ",D24) -> COMBO 3 VUELTA A CLASES 1 | G24: =A24 -> DESHABILITADOS
A25: DESHABILITADOS | B25: 30 - 0 | C25: HUEVOS + MINI BEBIDA | D25: 2 x 5 GRM | E25: =VALUE(SUBSTITUTE(SUBSTITUTE(B25," ",""),"-","")) -> 300 | F25: =+CONCATENATE(C25," ",D25) -> HUEVOS + MINI BEBIDA 2 x 5 GRM | G25: =A25 -> DESHABILITADOS
A26: CAFES | B26: 36 - 0 | C26: NESCAFE TRADICIÓN TARRO | D26: 9 x 6 x 50 GRS | E26: =VALUE(SUBSTITUTE(SUBSTITUTE(B26," ",""),"-","")) -> 360 | F26: =+CONCATENATE(C26," ",D26) -> NESCAFE TRADICIÓN TARRO 9 x 6 x 50 GRS | G26: =A26 -> CAFES
A27: CAFES | B27: 37 - 0 | C27: NESCAFE TRADICIÓN TARRO | D27: 9 x 6 x 50 GRM | E27: =VALUE(SUBSTITUTE(SUBSTITUTE(B27," ",""),"-","")) -> 370 | F27: =+CONCATENATE(C27," ",D27) -> NESCAFE TRADICIÓN TARRO 9 x 6 x 50 GRM | G27: =A27 -> CAFES
A28: DESHABILITADOS | B28: 39 - 0 | C28: MCKAY VINO VO | D28: 28 x 155 GRM | E28: =VALUE(SUBSTITUTE(SUBSTITUTE(B28," ",""),"-","")) -> 390 | F28: =+CONCATENATE(C28," ",D28) -> MCKAY VINO VO 28 x 155 GRM | G28: =A28 -> DESHABILITADOS
A29: OPPB | B29: 40 - 0 | C29: NESQUIK NUTRB Frutilla | D29: 8 x 20 x 15 GRM | E29: =VALUE(SUBSTITUTE(SUBSTITUTE(B29," ",""),"-","")) -> 400 | F29: =+CONCATENATE(C29," ",D29) -> NESQUIK NUTRB Frutilla 8 x 20 x 15 GRM | G29: =A29 -> OPPB
A30: OPPB | B30: 41 - 0 | C30: NESQUIK FRUTILLA | D30: 8 x 20 x 15 GRM | E30: =VALUE(SUBSTITUTE(SUBSTITUTE(B30," ",""),"-","")) -> 410 | F30: =+CONCATENATE(C30," ",D30) -> NESQUIK FRUTILLA 8 x 20 x 15 GRM | G30: =A30 -> OPPB
A31: DESHABILITADOS | B31: 43 - 0 | C31: Maq Afeitar + S.Nuss 250 gr | D31: 1 | E31: =VALUE(SUBSTITUTE(SUBSTITUTE(B31," ",""),"-","")) -> 430 | F31: =+CONCATENATE(C31," ",D31) -> Maq Afeitar + S.Nuss 250 gr 1 | G31: =A31 -> DESHABILITADOS
A32: DESHABILITADOS | B32: 44 - 0 | C32: Regalo Pack x Galletas | D32: 1 | E32: =VALUE(SUBSTITUTE(SUBSTITUTE(B32," ",""),"-","")) -> 440 | F32: =+CONCATENATE(C32," ",D32) -> Regalo Pack x Galletas 1 | G32: =A32 -> DESHABILITADOS
A33: CAFES | B33: 47 - 0 | C33: PACK CAFE 1 | D33: 1 | E33: =VALUE(SUBSTITUTE(SUBSTITUTE(B33," ",""),"-","")) -> 470 | F33: =+CONCATENATE(C33," ",D33) -> PACK CAFE 1 1 | G33: =A33 -> CAFES
A34: DESHABILITADOS | B34: 49 - 0 | C34: PROMO JUGO | E34: =VALUE(SUBSTITUTE(SUBSTITUTE(B34," ",""),"-","")) -> 490 | F34: =+CONCATENATE(C34," ",D34) -> PROMO JUGO | G34: =A34 -> DESHABILITADOS
A35: GALLETAS | B35: 52 - 0 | C35: PACK TRITON+KUKY+MTORTA | D35: 1 | E35: =VALUE(SUBSTITUTE(SUBSTITUTE(B35," ",""),"-","")) -> 520 | F35: =+CONCATENATE(C35," ",D35) -> PACK TRITON+KUKY+MTORTA 1 | G35: =A35 -> GALLETAS
A36: CULINARIOS | B36: 54 - 0 | C36: PACK CULINARIO 1 | D36: 1 | E36: =VALUE(SUBSTITUTE(SUBSTITUTE(B36," ",""),"-","")) -> 540 | F36: =+CONCATENATE(C36," ",D36) -> PACK CULINARIO 1 1 | G36: =A36 -> CULINARIOS
A37: CULINARIOS | B37: 55 - 0 | C37: PACK CULINARIO 2 | D37: 1 | E37: =VALUE(SUBSTITUTE(SUBSTITUTE(B37," ",""),"-","")) -> 550 | F37: =+CONCATENATE(C37," ",D37) -> PACK CULINARIO 2 1 | G37: =A37 -> CULINARIOS
A38: CAFES | B38: 56 - 0 | C38: PACK CAFE | D38: 1 | E38: =VALUE(SUBSTITUTE(SUBSTITUTE(B38," ",""),"-","")) -> 560 | F38: =+CONCATENATE(C38," ",D38) -> PACK CAFE 1 | G38: =A38 -> CAFES
A39: DESHABILITADOS | B39: 58 - 0 | C39: MUEBLE CHOCO ESCALON | D39: 1 | E39: =VALUE(SUBSTITUTE(SUBSTITUTE(B39," ",""),"-","")) -> 580 | F39: =+CONCATENATE(C39," ",D39) -> MUEBLE CHOCO ESCALON 1 | G39: =A39 -> DESHABILITADOS
A40: DESHABILITADOS | B40: 59 - 0 | C40: GANCHERAS PROMOCION | D40: 1 | E40: =VALUE(SUBSTITUTE(SUBSTITUTE(B40," ",""),"-","")) -> 590 | F40: =+CONCATENATE(C40," ",D40) -> GANCHERAS PROMOCION 1 | G40: =A40 -> DESHABILITADOS
A41: CAFES | B41: 60 - 0 | C41: PACK CAFE CUCHARA | D41: 1 | E41: =VALUE(SUBSTITUTE(SUBSTITUTE(B41," ",""),"-","")) -> 600 | F41: =+CONCATENATE(C41," ",D41) -> PACK CAFE CUCHARA 1 | G41: =A41 -> CAFES
...

Sheet Concuna
A1: Index | B1: Posicion | C1: COD | D1: Posición2 | E1: SKU | F1: MEDIDA | G1: BARRAS UNIDADES | H1: BARRAS DISPLAY | I1: BARRAS CAJAS | J1: DISPLAY x CAJA | K1: CATEGORIA | L1: COD2 | M1: BARRAS CAJAS3 | P1: Posicion | Q1: Sin Stock
A2: 1 | B2: Posicion A01 | C2: 46694 | D2: Posición A01 | E2: NATURNES Carne Verduras 4(6x205g) CL | F2: 4(6x205g) | G2: 8445291769885 | I2: 8445291769908 | K2: TRADICIONAL | L2: A01 | M2: cajas | N2: A01 | O2: A01 | P2: Igual | Q2: 10618
A3: 2 | B3: Posicion A02 | C3: 46669 | D3: Posición A02 | E3: NATURNES Pollo Verduras 4(6x205g) CL | F3: 4(6x205g) | G3: 8445291770218 | I3: 8445291770232 | K3: TRADICIONAL | L3: A02 | M3: cajas | N3: A02 | O3: A02 | P3: Igual | Q3: 117723
A4: 3 | B4: Posicion A03 | C4: 46695 | D4: Posición A03 | E4: NATURNES AIP Carne Verduras 4(6x205g) CL | F4: 4(6x205g) | G4: 8445291770027 | I4: 8445291770041 | K4: TRADICIONAL | L4: A03 | M4: cajas | N4: A03 | O4: A03 | P4: Igual | Q4: 124520
A5: 4 | B5: Posicion A04 | C5: 46716 | D5: Posición A04 | E5: NESTLE AIP Pollo Verduras 4(6x205g) CL | F5: 4(6x205g) | G5: 8445292266062 | I5: 8445292266086 | K5: TRADICIONAL | L5: A04 | M5: cajas | N5: A04 | O5: A04 | P5: Igual | Q5: 2784
A6: 5 | B6: Posicion A05 | C6: 46730 | D6: Posición A05 | E6: Picado NESTLE NATURNES Carbonada12x250g | F6: 12x250g | G6: 7613030264569 | I6: 7613033207266 | K6: TRADICIONAL | L6: A05 | M6: cajas | N6: A05 | O6: A05 | P6: Igual | Q6: 13510
A7: 6 | B7: Posicion A06 | C7: 46740 | D7: Posición A06 | E7: Picado NESTLE NATURNES Cazuela de Ave 24x250g | F7: 24x250g | G7: 7613030264705 | I7: 7613031415090 | K7: TRADICIONAL | L7: A06 | M7: cajas | N7: A06 | O7: A06 | P7: Igual | Q7: 11310
A8: 7 | B8: Posicion A07 | C8: 46750 | D8: Posición A07 | E8: Picado NESTLE NATURNES Cazuela de Vacuno24x250g | F8: 24x250g | G8: 7613030692669 | I8: 7613031415113 | K8: TRADICIONAL | L8: A07 | M8: cajas | N8: A07 | O8: A07 | P8: Igual | Q8: 11711
A9: 8 | B9: Posicion A08 | C9: 46760 | D9: Posición A08 | E9: Picado NESTLE NATURNES Charquican12x250g | F9: 12x250g | G9: 7613030692577 | I9: 7613033207020 | K9: TRADICIONAL | L9: A08 | M9: cajas | N9: A08 | O9: A08 | P9: Igual | Q9: 1170
A10: 9 | B10: Posicion A09 | C10: 5670 | D10: Posición A09 | E10: Colado NESTLE NATURNES Carne Verdura 8(6x115g) | F10: 8(6x115g) | G10: 7613036653961 | I10: 7613036653985 | K10: TRADICIONAL | L10: A09 | M10: cajas | N10: A09 | O10: A09 | P10: Igual | Q10: 1235
A11: 10 | B11: Posicion A10 | C11: 56420 | D11: Posición A10 | E11: Colado NESTLE NATURNES Pollo Verduras 8x6x115g | F11: 8(6x115g) | G11: 7613036749565 | I11: 7613036654098 | K11: TRADICIONAL | L11: A10 | M11: cajas | N11: A10 | O11: A10 | P11: Igual | Q11: 1360
A12: 11 | B12: Posicion A11 | C12: 1330 | D12: Posición A11 | E12: Crema de leche NESTLE Lata48 x 157 GRM | F12: 48 x 157 GRM | G12: 7613032414580 | I12: 7613032414597 | K12: TRADICIONAL | L12: A11 | M12: cajas | N12: A11 | O12: A11 | P12: Igual | Q12: 7656
A13: 12 | B13: Posicion A11 | C13: 79760 | D13: Posición A11 | E13: NESTLE Crema de leche tarro 3840x157g | F13: 3840x157g | G13: 7613032414580 | I13: 7613287221766 | K13: TRADICIONAL | L13: A11 | M13: PDQ | N13: A11 | O13: A11 | P13: Igual | Q13: 0
... A54: 53 | B54: Posicion C01 | C54: 36535 | D54: Posición C01 | E54: NESCAFE CAPPUCCINO 6(8x14g) N2 CL | F54: 6(8x14g) | G54: 8445291239043 | I54: 8445291239012 | K54: TRADICIONAL | L54: C01 | M54: cajas | N54: C01 | O54: C01 | P54: Igual | Q54: 0
A55: 54 | B55: Posicion C02 | C55: 5320 | D55: Posición C02 | E55: Cafe NESCAFE Tradicion sobres77x172.8g | F55: 77x172.8g | G55: 7613035671621 | I55: 7613035671638 | J55: 77 | K55: TRADICIONAL | L55: C02 | M55: cajas | N55: C02 | O55: C02 | P55: Igual | Q55: 0
A56: 55 | B56: Posicion C03 | C56: 38850 | D56: Posición C03 | E56: Cafe NESCAFE Tradicion tarro24 X 50 gr. | F56: 24 X 50 gr. | G56: 7802950002119 | I56: 7613034092472 | K56: TRADICIONAL | L56: C03 | M56: cajas | N56: C03 | O56: C03 | P56: Igual | Q56: 14282
A57: 56 | B57: Posicion C04 | C57: 2130 | D57: Posición C04 | E57: Cafe NESCAFE Tradicion tarro24 x 100 GRS | F57: 24 x 100 GRS | G57: 7802950002133 | I57: 17802950002130 | K57: TRADICIONAL | L57: C04 | M57: cajas | N57: C04 | O57: C04 | P57: Igual | Q57: 40419
A58: 57 | B58: Posicion C05 | C58: 2120 | D58: Posición C05 | E58: Cafe NESCAFE Tradicion tarro24 x 170 GRS | F58: 24 x 170 GRS | G58: 7802950002126 | I58: 17802950002123 | K58: TRADICIONAL | L58: C05 | M58: cajas | N58: C05 | O58: C05 | P58: Igual | Q58: 61920
A59: 58 | B59: Posicion C06 | C59: 50940 | D59: Posición C06 | E59: Cafe NESCAFE Tradicion tarro12X400G | F59: 12X400G | G59: 7802950002720 | I59: 17802950002727 | K59: TRADICIONAL | L59: C06 | M59: cajas | N59: C06 | O59: C06 | P59: Igual | Q59: 558
A60: 59 | B60: Posicion C07 | C60: 96570 | D60: Posición C07 | E60: NESTUM BL Prob CI 5Cereales 24x250gN1CL | F60: 24x250gN1CL | G60: 7613035939110 | I60: 7613035939127 | K60: TRADICIONAL | L60: C07 | M60: cajas | N60: C07 | O60: C07 | P60: Igual | Q60: 0
A61: 60 | B61: Posicion C08 | C61: 11780 | D61: Posición C08 | E61: Cereal infantil NESTUM Arroz24x250g | F61: 24x250g | G61: 7613036048132 | I61: 7613036048149 | K61: TRADICIONAL | L61: C08 | M61: cajas | N61: C08 | O61: C08 | P61: Igual | Q61: 201
A62: 61 | B62: Posicion C09 | C62: 90000 | D62: Posición C09 | E62: NESTUM BL Prob CI TrigoFruta 24x250gN2CL | F62: 24x250gN2CL | G62: 7613035939400 | I62: 7613035939417 | K62: TRADICIONAL | L62: C09 | M62: cajas | N62: C09 | O62: C09 | P62: Igual | Q62: 0
A63: 62 | B63: Posicion C10 | C63: 99020 | D63: Posición C10 | E63: NESTUM BL PROB CI TrigoMiel 24x250gN1CL | F63: 24x250gN1CL | G63: 7613035939370 | I63: 7613035939387 | K63: TRADICIONAL | L63: C10 | M63: cajas | N63: C10 | O63: C10 | P63: Igual | Q63: 0
A64: 63 | B64: Posicion C11 | C64: 11790 | D64: Posición C11 | E64: Cereal infantil NESTUM Avena y Arroz24x250g | F64: 24x250g | G64: 7613036048040 | I64: 7613036048057 | K64: TRADICIONAL | L64: C11 | M64: cajas | N64: C11 | O64: C11 | P64: Igual | Q64: 2113
A65: 64 | B65: Posicion C14 | C65: 69780 | D65: Posición C14 | E65: NESTLE EL MANJAR Bolsa 48x200g | F65: 48x200g | G65: 7802950009408 | I65: 8445290882585 | K65: TRADICIONAL | L65: C14 | M65: cajas | N65: C14 | O65: C14 | P65: Igual | Q65: 62920
A66: 65 | B66: Posicion C15 | C66: 43020 | D66: Posición C15 | E66: Manjar NESTLE El Manjar24x500g | F66: 24x500g | G66: 7802950009415 | I66: 17802950009412 | K66: TRADICIONAL | L66: C15 | M66: cajas | N66: C15 | O66: C15 | P66: Igual | Q66: 26920
A67: 66 | B67: Posicion C16 | C67: 72290 | D67: Posición C16 | E67: Manjar NESTLE El Manjar Doypack12x800g | F67: 12x800g | G67: 7613038639161 | I67: 7613038639178 | K67: TRADICIONAL | L67: C16 | M67: cajas | N67: C16 | O67: C16 | P67: Igual | Q67: 1691
... A127: 126 | B127: Posicion E25 | C127: 12310 | D127: Posición E25 | E127: Salsa de tomate MAGGI Tuco con Carne Lata24 x 245 GRS | F127: 24 x 245 GRS | G127: 7802950012316 | I127: 17802950012313 | K127: TRADICIONAL | L127: E25 | M127: cajas | N127: E25 | O127: E25 | P127: Igual | Q127: 17
A128: 127 | B128: Posicion E26 | C128: 5110 | D128: Posición E26 | E128: IMPERIAL POLVO HORNEAR SOBRE10 x 50 x 20 GRM | F128: 10 x 50 x 20 GRM | G128: 7802950105117 | H128: 7802950105117 | I128: 17802950005117 | K128: TRADICIONAL | L128: E26 | M128: cajas | N128: E26 | O128: E26 | P128: Igual | Q128: 11480
A129: 128 | B129: Posicion F01 | C129: 8770 | D129: Posición F01 | E129: Polvo de hornear IMPERIAL Sobres6 x 12 x 100 GRM | F129: 6 x 12 x 100 GRM | G129: 7802950108774 | H129: 7802950108774 | I129: 17802950008774 | K129: TRADICIONAL | L129: F01 | M129: cajas | N129: F01 | O129: F01 | P129: Igual | Q129: 3930
A130: 129 | B130: Posicion F02 | C130: 5020 | D130: Posición F02 | E130: Polvo de hornear IMPERIAL Lata24 x 200 GRM | F130: 24 x 200 GRM | G130: 7802950005028 | I130: 17802950005025 | K130: TRADICIONAL | L130: F02 | M130: cajas | N130: F02 | O130: F02 | P130: Igual | Q130: 24523
A131: 130 | B131: Posicion F03 | C131: 35700 | D131: Posición F03 | E131: STARBUCKS Caramel Latte 10(4x23)g N3 XJ | F131: 10(4x23)g | G131: 8445290216816 | I131: 8445290216700 | K131: TRADICIONAL | L131: F03 | M131: cajas | N131: F03 | O131: F03 | P131: Igual | Q131: 469
A132: 131 | B132: Posicion F04 | C132: 35710 | D132: Posición F04 | E132: STARBUCKS Mocha 1(4x22)g N3 XJ | F132: 10(4x22)g | G132: 7613038631189 | I132: 7613038630373 | K132: TRADICIONAL | L132: F04 | M132: cajas | N132: F04 | O132: F04 | P132: Igual | Q132: 600
A133: 132 | B133: Posicion F05 | C133: 96670 | D133: Posición F05 | E133: NATURNES Organico Manzana Pouch 16x100gCL | F133: 16x100gCL | G133: 7506475110303 | I133: 17506475110300 | K133: TRADICIONAL | L133: F05 | M133: cajas | N133: F05 | O133: F05 | P133: Igual | Q133: 0
A134: 133 | B134: Posicion F06 | C134: 96630 | D134: Posición F06 | E134: NATURNESOrganicoPlatanoMangoPch 16x100gCL | F134: 16x100gCL | G134: 7506475110280 | I134: 17506475110287 | K134: TRADICIONAL | L134: F06 | M134: cajas | N134: F06 | O134: F06 | P134: Igual | Q134: 0
A135: 134 | B135: Posicion F07 | C135: 77370 | D135: Posición F07 | E135: NESC DLC GST Skny Capp N1XR 16Cap3x161.6g | F135: 16Cap3x161.6g | G135: 7613031587377 | I135: 17501059273709 | K135: TRADICIONAL | L135: F07 | M135: cajas | N135: F07 | O135: F07 | P135: Igual | Q135: 0
A136: 135 | B136: Posicion F08 | C136: 63401 | D136: Posición F08 | E136: NDG AMERICANO 10Caps 6x80g XR | F136: 6x80g | G136: 7891000405772 | I136: 17891000405779 | K136: TRADICIONAL | L136: F08 | M136: cajas | N136: F08 | O136: F08 | P136: Igual | Q136: 0
A137: 136 | B137: Posicion F09 | C137: 36920 | D137: Posición F09 | E137: STARBUCKS Vanilla Latte 10(4x215g)N3 XJ | F137: 4x21.5g | G137: 7613038630977 | I137: 7613038630960 | K137: TRADICIONAL | L137: F09 | M137: cajas | N137: F09 | O137: F09 | P137: Igual | Q137: 433
A138: 137 | B138: Posicion F10 | C138: 976901 | D138: Posición F10 | E138: NDG MOCHA 10Caps 6x135g XR | F138: 6x135g | G138: 7891000405871 | I138: 17891000405878 | K138: TRADICIONAL | L138: F10 | M138: cajas | N138: F10 | O138: F10 | P138: Igual | Q138: 0
A139: 138 | B139: Posicion F11 | C139: 8760 | D139: Posición F11 | E139: NIDO SmDescr Chocolate 19%MG 15x700g CL | F139: 15x700g CL | G139: 8445291195509 | I139: 8445291195615 | K139: TRADICIONAL | L139: F11 | M139: cajas | N139: F11 | O139: F11 | P139: Igual | Q139: 0
...

Sheet Etiquetas
A1: 1 | B1: =+VLOOKUP(A1,'Sectorizacion Racks'!$A$2:$F$1332,5,FALSE) -> A1 | C1: =+VLOOKUP(A1+1,'Sectorizacion Racks'!$A$2:$F$1332,5,FALSE) -> A2 | E1: A1 | F1: A2
A2: =+A1+2 -> 3 | B2: =+VLOOKUP(A2,'Sectorizacion Racks'!$A$2:$F$1332,5,FALSE) -> A3 | C2: =+VLOOKUP(A2+1,'Sectorizacion Racks'!$A$2:$F$1332,5,FALSE) -> A4 | E2: A3 | F2: A4
A3: =+A2+2 -> 5 | B3: =+VLOOKUP(A3,'Sectorizacion Racks'!$A$2:$F$1332,5,FALSE) -> A5 | C3: =+VLOOKUP(A3+1,'Sectorizacion Racks'!$A$2:$F$1332,5,FALSE) -> A6 | E3: A5 | F3: A6
A4: =+A3+2 -> 7 | B4: =+VLOOKUP(A4,'Sectorizacion Racks'!$A$2:$F$1332,5,FALSE) -> A7 | C4: =+VLOOKUP(A4+1,'Sectorizacion Racks'!$A$2:$F$1332,5,FALSE) -> A8 | E4: A7 | F4: A8
A5: =+A4+2 -> 9 | B5: =+VLOOKUP(A5,'Sectorizacion Racks'!$A$2:$F$1332,5,FALSE) -> A9 | C5: =+VLOOKUP(A5+1,'Sectorizacion Racks'!$A$2:$F$1332,5,FALSE) -> A10 | E5: A9 | F5: A10
A6: =+A5+2 -> 11 | B6: =+VLOOKUP(A6,'Sectorizacion Racks'!$A$2:$F$1332,5,FALSE) -> A11 | C6: =+VLOOKUP(A6+1,'Sectorizacion Racks'!$A$2:$F$1332,5,FALSE) -> A12 | E6: A11 | F6: A12
A7: =+A6+2 -> 13 | B7: =+VLOOKUP(A7,'Sectorizacion Racks'!$A$2:$F$1332,5,FALSE) -> A13 | C7: =+VLOOKUP(A7+1,'Sectorizacion Racks'!$A$2:$F$1332,5,FALSE) -> A14 | E7: A13 | F7: A14
A8: =+A7+2 -> 15 | B8: =+VLOOKUP(A8,'Sectorizacion Racks'!$A$2:$F$1332,5,FALSE) -> A15 | C8: =+VLOOKUP(A8+1,'Sectorizacion Racks'!$A$2:$F$1332,5,FALSE) -> A16 | E8: A15 | F8: A16
A9: =+A8+2 -> 17 | B9: =+VLOOKUP(A9,'Sectorizacion Racks'!$A$2:$F$1332,5,FALSE) -> A17 | C9: =+VLOOKUP(A9+1,'Sectorizacion Racks'!$A$2:$F$1332,5,FALSE) -> A18 | E9: A17 | F9: A18
A10: =+A9+2 -> 19 | B10: =+VLOOKUP(A10,'Sectorizacion Racks'!$A$2:$F$1332,5,FALSE) -> A19 | C10: =+VLOOKUP(A10+1,'Sectorizacion Racks'!$A$2:$F$1332,5,FALSE) -> A20 | E10: A19 | F10: A20
A11: =+A10+2 -> 21 | B11: =+VLOOKUP(A11,'Sectorizacion Racks'!$A$2:$F$1332,5,FALSE) -> A21 | C11: =+VLOOKUP(A11+1,'Sectorizacion Racks'!$A$2:$F$1332,5,FALSE) -> A22 | E11: A21 | F11: A22
A12: =+A11+2 -> 23 | B12: =+VLOOKUP(A12,'Sectorizacion Racks'!$A$2:$F$1332,5,FALSE) -> A23 | C12: =+VLOOKUP(A12+1,'Sectorizacion Racks'!$A$2:$F$1332,5,FALSE) -> A24 | E12: A23 | F12: A24
A13: =+A12+2 -> 25 | B13: =+VLOOKUP(A13,'Sectorizacion Racks'!$A$2:$F$1332,5,FALSE) -> B1 | C13: =+VLOOKUP(A13+1,'Sectorizacion Racks'!$A$2:$F$1332,5,FALSE) -> B2 | E13: B1 | F13: B2
... A382: =+A381+2 -> 763 | B382: =+VLOOKUP(A382,'Sectorizacion Racks'!$A$2:$F$1332,5,FALSE) -> A4 | C382: =+VLOOKUP(A382+1,'Sectorizacion Racks'!$A$2:$F$1332,5,FALSE) -> A5 | E382: B1 | F382: B2
